Workbook

Sheet Dashboard
B1: CoopBank Website Redesign
B2: SG-2026-0101 | Cooperative Bank Tanzania Plc.
B4: Total Tasks | C4: Completed | D4: In Progress | E4: Blocked/Awaiting | F4: Completion %
B5: =COUNTA(Tasks!A4:A200) | C5: =COUNTIF(Tasks!E4:E200,"Complete") | D5: =COUNTIF(Tasks!E4:E200,"In Progress") | E5: =COUNTIF(Tasks!E4:E200,"Blocked")+COUNTIF(Tasks!E4:E200,"Awaiting Client") | F5: =IFERROR(ROUND(COUNTIF(Tasks!E4:E200,"Complete")/COUNTA(Tasks!E4:E200)*100,1)&"%","0%")
B7: Milestone Progress
B8: Milestone | C8: Total | D8: Done | E8: In Progress | F8: Blocked | G8: Progress | H8: Status
B9: PM & Admin | C9: =COUNTIF(Tasks!C4:C200,B9) | D9: =COUNTIFS(Tasks!C4:C200,B9,Tasks!E4:E200,"Complete") | E9: =COUNTIFS(Tasks!C4:C200,B9,Tasks!E4:E200,"In Progress") | F9: =COUNTIFS(Tasks!C4:C200,B9,Tasks!E4:E200,"Blocked")+COUNTIFS(Tasks!C4:C200,B9,Tasks!E4:E200,"Awaiting Client") | G9: =IFERROR(ROUND(D9/C9*100,0)&"%","0%") | H9: =IF(G9="100%","Done",IF(E9>0,"Active",IF(F9>0,"Blocked","Pending")))
B10: Discovery & Planning | C10: =COUNTIF(Tasks!C4:C200,B10) | D10: =COUNTIFS(Tasks!C4:C200,B10,Tasks!E4:E200,"Complete") | E10: =COUNTIFS(Tasks!C4:C200,B10,Tasks!E4:E200,"In Progress") | F10: =COUNTIFS(Tasks!C4:C200,B10,Tasks!E4:E200,"Blocked")+COUNTIFS(Tasks!C4:C200,B10,Tasks!E4:E200,"Awaiting Client") | G10: =IFERROR(ROUND(D10/C10*100,0)&"%","0%") | H10: =IF(G10="100%","Done",IF(E10>0,"Active",IF(F10>0,"Blocked","Pending")))
B11: Design & Build | C11: =COUNTIF(Tasks!C4:C200,B11) | D11: =COUNTIFS(Tasks!C4:C200,B11,Tasks!E4:E200,"Complete") | E11: =COUNTIFS(Tasks!C4:C200,B11,Tasks!E4:E200,"In Progress") | F11: =COUNTIFS(Tasks!C4:C200,B11,Tasks!E4:E200,"Blocked")+COUNTIFS(Tasks!C4:C200,B11,Tasks!E4:E200,"Awaiting Client") | G11: =IFERROR(ROUND(D11/C11*100,0)&"%","0%") | H11: =IF(G11="100%","Done",IF(E11>0,"Active",IF(F11>0,"Blocked","Pending")))
B12: Client Review & Revisions | C12: =COUNTIF(Tasks!C4:C200,B12) | D12: =COUNTIFS(Tasks!C4:C200,B12,Tasks!E4:E200,"Complete") | E12: =COUNTIFS(Tasks!C4:C200,B12,Tasks!E4:E200,"In Progress") | F12: =COUNTIFS(Tasks!C4:C200,B12,Tasks!E4:E200,"Blocked")+COUNTIFS(Tasks!C4:C200,B12,Tasks!E4:E200,"Awaiting Client") | G12: =IFERROR(ROUND(D12/C12*100,0)&"%","0%") | H12: =IF(G12="100%","Done",IF(E12>0,"Active",IF(F12>0,"Blocked","Pending")))
B13: Content & Localization | C13: =COUNTIF(Tasks!C4:C200,B13) | D13: =COUNTIFS(Tasks!C4:C200,B13,Tasks!E4:E200,"Complete") | E13: =COUNTIFS(Tasks!C4:C200,B13,Tasks!E4:E200,"In Progress") | F13: =COUNTIFS(Tasks!C4:C200,B13,Tasks!E4:E200,"Blocked")+COUNTIFS(Tasks!C4:C200,B13,Tasks!E4:E200,"Awaiting Client") | G13: =IFERROR(ROUND(D13/C13*100,0)&"%","0%") | H13: =IF(G13="100%","Done",IF(E13>0,"Active",IF(F13>0,"Blocked","Pending")))
B14: Testing & QA | C14: =COUNTIF(Tasks!C4:C200,B14) | D14: =COUNTIFS(Tasks!C4:C200,B14,Tasks!E4:E200,"Complete") | E14: =COUNTIFS(Tasks!C4:C200,B14,Tasks!E4:E200,"In Progress") | F14: =COUNTIFS(Tasks!C4:C200,B14,Tasks!E4:E200,"Blocked")+COUNTIFS(Tasks!C4:C200,B14,Tasks!E4:E200,"Awaiting Client") | G14: =IFERROR(ROUND(D14/C14*100,0)&"%","0%") | H14: =IF(G14="100%","Done",IF(E14>0,"Active",IF(F14>0,"Blocked","Pending")))
B15: Go-Live & Handover | C15: =COUNTIF(Tasks!C4:C200,B15) | D15: =COUNTIFS(Tasks!C4:C200,B15,Tasks!E4:E200,"Complete") | E15: =COUNTIFS(Tasks!C4:C200,B15,Tasks!E4:E200,"In Progress") | F15: =COUNTIFS(Tasks!C4:C200,B15,Tasks!E4:E200,"Blocked")+COUNTIFS(Tasks!C4:C200,B15,Tasks!E4:E200,"Awaiting Client") | G15: =IFERROR(ROUND(D15/C15*100,0)&"%","0%") | H15: =IF(G15="100%","Done",IF(E15>0,"Active",IF(F15>0,"Blocked","Pending")))
B18: Items Blocked on Client
B19: Task | C19: Tags | D19: Status | E19: Blocker Description
B20: =IFERROR(FILTER(Tasks!B4:B200, Tasks!E4:E200="Awaiting Client"), "No items awaiting client") | C20: =IFERROR(FILTER(Tasks!F4:F200, Tasks!E4:E200="Awaiting Client"), "")

Sheet Tasks
A1: SG-2026-0101 — CoopBank Task Tracker
A2: Use Status dropdown to update. Changes auto-color. Tags are comma-separated. Subtasks link to Subtasks tab.
A3: ID | B3: Task Name | C3: Milestone | D3: Owner | E3: Status | F3: Tags | G3: Priority | H3: Start Date | I3: Due Date | J3: Subtasks | K3: Dependencies / Notes
A4: 77 | B4: Weekly Client Status Update (CoopBank) | C4: PM & Admin | D4: Neema | E4: Awaiting Feedback | F4: Recurring | G4: High | H4: 2026-03-18 | I4: 2026-04-25 | K4: Weekly cadence
A5: 78 | B5: Invoice Preparation & Payment Follow-up | C5: PM & Admin | D5: Neema | E5: Not Started | F5: Finance | G5: High | H5: 2026-03-20 | I5: 2026-04-25 | K5: 40% commencement due
A6: 79 | B6: Project Timeline & Risk Management | C6: PM & Admin | D6: Neema | E6: Awaiting Feedback | F6: PM | G6: High | H6: 2026-03-18 | I6: 2026-04-25
A7: 80 | B7: Client Communication & Meeting Coordination | C7: PM & Admin | D7: Neema | E7: Awaiting Feedback | F7: PM | G7: High | H7: 2026-03-18 | I7: 2026-04-25
A8: 81 | B8: Contract & Scope Documentation | C8: PM & Admin | D8: Neema | E8: Awaiting Feedback | F8: Legal | G8: High | H8: 2026-03-20 | I8: 2026-03-22
A9: 48 | B9: Discovery & Stakeholder Requirements | C9: Discovery & Planning | D9: Jumbe + Neema | E9: Complete | F9: Research | G9: Medium | H9: 2026-03-06 | I9: 2026-03-08
A10: 49 | B10: Competitor Analysis (NMB, CRDB, NBC, Stanbic) | C10: Discovery & Planning | D10: Jumbe + Neema | E10: Complete | F10: Research | G10: Medium | H10: 2026-03-07 | I10: 2026-03-09
A11: 50 | B11: Sitemap & Information Architecture | C11: Discovery & Planning | D11: Jumbe + Neema | E11: Complete | F11: UX | G11: Medium | H11: 2026-03-08 | I11: 2026-03-10
A12: 51 | B12: Brand Asset Collection | C12: Discovery & Planning | D12: Neema | E12: Complete | F12: Design | G12: Medium | H12: 2026-03-08 | I12: 2026-03-11
A13: 52 | B13: Content Audit & Copywriting | C13: Discovery & Planning | D13: Jumbe + Neema | E13: Complete | F13: Content | G13: Medium | H13: 2026-03-09 | I13: 2026-03-14
A14: 53 | B14: Next.js Project Setup & Architecture | C14: Design & Build | D14: Jumbe | E14: Complete | F14: Dev | G14: Medium | H14: 2026-03-12 | I14: 2026-03-13
A15: 54 | B15: Homepage Build (Hero, Forex, Products, Stats) | C15: Design & Build | D15: Jumbe | E15: Complete | F15: Dev | G15: Medium | H15: 2026-03-13 | I15: 2026-03-15
A16: 55 | B16: Personal Banking & Loan Products Pages | C16: Design & Build | D16: Jumbe | E16: Complete | F16: Dev | G16: Medium | H16: 2026-03-15 | I16: 2026-03-16
A17: 56 | B17: Digital Banking Pages (CoopNet, Wakala, USSD, QR) | C17: Design & Build | D17: Jumbe | E17: Complete | F17: Dev | G17: Medium | H17: 2026-03-16 | I17: 2026-03-17
... A22: 61 | B22: GA4 Analytics & Staging Deployment | C22: Design & Build | D22: Jumbe | E22: Complete | F22: DevOps | G22: Medium | H22: 2026-03-17 | I22: 2026-03-18
A23: 62 | B23: Submit First Draft to CoopBank Marketing | C23: Client Review & Revisions | D23: Jumbe + Neema | E23: Complete | F23: Milestone | G23: Medium | H23: 2026-03-18 | I23: 2026-03-18 | K23: Sent to Oscar Rubasha
A24: 63 | B24: Collect Client Feedback (Round 1) | C24: Client Review & Revisions | D24: Neema | E24: Complete | F24: Client | G24: High | H24: 2026-03-18 | I24: 2026-03-25 | K24: Received 2026-03-26
A25: 64 | B25: Implement Design Revisions (Round 1) | C25: Client Review & Revisions | D25: Jumbe | E25: Complete | F25: Dev | G25: Medium | H25: 2026-03-25 | I25: 2026-03-29 | K25: Colors, forex, products, cards, content
A26: 65 | B26: Collect Client Feedback (Round 2) | C26: Client Review & Revisions | D26: Neema | E26: Not Started | F26: Client | G26: Medium | H26: 2026-03-29 | I26: 2026-04-01 | K26: After pending builds complete
A27: 109 | B27: Implement Design Revisions (Round 2) | C27: Client Review & Revisions | E27: Not Started | F27: Dev | G27: Medium | K27: Depends on: Round 2 feedback
A28: 110 | B28: Collect Client Feedback (Round 3 - Final) | C28: Client Review & Revisions | E28: Not Started | F28: Client | G28: Medium | K28: Final review before QA
A29: 111 | B29: Implement Final Revisions (Round 3) | C29: Client Review & Revisions | E29: Not Started | F29: Dev | G29: Medium | K29: Last changes before testing
A30: 82 | B30: Build: Business Banking Page | C30: Client Review & Revisions | D30: Jumbe | E30: Not Started | F30: Build | G30: Medium | H30: 2026-03-27 | I30: 2026-03-29 | J30: 0/10
A31: 83 | B31: Build: Contact Us Page | C31: Client Review & Revisions | D31: Jumbe | E31: Not Started | F31: Build | G31: Medium | H31: 2026-03-27 | I31: 2026-03-28 | J31: 0/10 | K31: Needs: email domain (#113)
A32: 84 | B32: Build: FAQs Page | C32: Client Review & Revisions | D32: Jumbe | E32: Not Started | F32: Build | G32: Medium | H32: 2026-03-28 | I32: 2026-03-29 | J32: 0/13
A33: 85 | B33: Build: Blog / News & Updates Page | C33: Client Review & Revisions | D33: Jumbe | E33: Not Started | F33: Build | G33: Medium | H33: 2026-03-29 | I33: 2026-03-31 | J33: 0/10
A34: 86 | B34: Build: Privacy Policy & Terms Pages | C34: Client Review & Revisions | D34: Neema | E34: Not Started | F34: Build, Legal | G34: Medium | H34: 2026-03-29 | I34: 2026-03-30 | J34: 0/8 | K34: Needs: approved legal content
A35: 87 | B35: Build: Cookie Consent Banner | C35: Client Review & Revisions | D35: Jumbe | E35: Not Started | F35: Build | G35: Medium | H35: 2026-03-30 | I35: 2026-03-30 | J35: 0/9
A36: 89 | B36: Figma Design System: Complete & Deliver | C36: Client Review & Revisions | D36: Jumbe | E36: Not Started | F36: Design | G36: Low | H36: 2026-03-29 | I36: 2026-04-03 | K36: Deliverable to client
A37: 90 | B37: Figma: Component Library & Style Guide | C37: Client Review & Revisions | D37: Jumbe | E37: Not Started | F37: Design | G37: Medium | H37: 2026-04-01 | I37: 2026-04-03
A38: 112 | B38: Awaiting: Official Product Master List | C38: Client Review & Revisions | D38: Oscar (CBT) | E38: Awaiting Client | F38: Blocker, Products | G38: Critical | J38: 0/7 | K38: Msomi vs Wanafunzi, Mafao etc.
A39: 113 | B39: Awaiting: Email Domain Confirmation | C39: Client Review & Revisions | D39: CBT IT | E39: Awaiting Client | F39: Blocker, Config | G39: Critical | J39: 0/8 | K39: @coopbank vs @cbtbank
A40: 114 | B40: Awaiting: Brand Guide / Visual Reference | C40: Client Review & Revisions | D40: CBT Marketing | E40: Awaiting Client | F40: Blocker, Design | G40: High | J40: 0/9 | K40: Dashed white unclear
A41: 115 | B41: Awaiting: About Us Content (Bank-Approved) | C41: Client Review & Revisions | D41: Oscar (CBT) | E41: Awaiting Client | F41: Blocker, Content | G41: Critical | J41: 0/11 | K41: Mission, Vision, Values, Story
A42: 116 | B42: Awaiting: Account Opening CTAs | C42: Client Review & Revisions | D42: CBT Ops | E42: Awaiting Client | F42: Blocker, UX | G42: Critical | J42: 0/12 | K42: Where do buttons link?
A43: 117 | B43: Awaiting: Agent Application Form | C43: Client Review & Revisions | D43: CBT Ops | E43: Awaiting Client | F43: Blocker, UX | G43: High | J43: 0/7 | K43: Destination unknown
A44: 66 | B44: Swahili Translation - All Pages | C44: Content & Localization | D44: Neema | E44: Not Started | F44: i18n | G44: Medium | H44: 2026-04-01 | I44: 2026-04-07 | J44: 0/15
...

Sheet Subtasks
A1: Subtask Details — Check Done when complete
A2: Task ID | B2: Task Name | C2: Subtask | D2: Done | E2: Assigned To | F2: Notes
A3: 82 | B3: Build: Business Banking Page | C3: Design hero section with glassmorphism panel
A4: 82 | C4: Build Business Current Account section (TZS, USD, EUR, GBP)
A5: 82 | C5: Build Business Savings Account section
A6: 82 | C6: Build Trade Finance section (LCs, guarantees, bills)
A7: 82 | C7: Build Cash Management section
A8: 82 | C8: Build Payroll Services section
A9: 82 | C9: Build Business Loans overview with CTA
A10: 82 | C10: Add product comparison table
A11: 82 | C11: Add Open Business Account CTA (pending destination)
A12: 82 | C12: Mobile responsive layout and testing
A13: 83 | B13: Build: Contact Us Page | C13: Build hero with contact information cards
A14: 83 | C14: Add phone: +255 27 275 4470
A15: 83 | C15: Add email (pending domain confirmation)
A16: 83 | C16: Build contact form (name, email, phone, subject, message)
A17: 83 | C17: Add form validation and submission handler
A18: 83 | C18: Embed Google Maps with HQ pin
A19: 83 | C19: Add operating hours section
A20: 83 | C20: Add social media links
A21: 83 | C21: Add quick links to Branch/Agent Locator
A22: 83 | C22: Mobile responsive layout
A23: 84 | B23: Build: FAQs Page | C23: Design FAQ layout with category tabs
A24: 84 | C24: Create categories: General, Accounts, Digital, Loans, Cards, Wakala
A25: 84 | C25: Build accordion components
A26: 84 | C26: Write General FAQs
A27: 84 | C27: Write Account FAQs
A28: 84 | C28: Write Digital Banking FAQs
A29: 84 | C29: Write Loans FAQs
A30: 84 | C30: Write Cards FAQs
A31: 84 | C31: Write Wakala FAQs
A32: 84 | C32: Add search/filter functionality
A33: 84 | C33: Add CTA to Contact Us
A34: 84 | C34: SEO: FAQ schema markup (JSON-LD)
A35: 84 | C35: Mobile responsive accordion
A36: 85 | B36: Build: Blog / News Page | C36: Design blog listing with featured hero
A37: 85 | C37: Build blog card grid
A38: 85 | C38: Build individual post template
A39: 85 | C39: Add category filter
A40: 85 | C40: Add pagination
...

Sheet Gantt
A1: Project Timeline (Gantt) | AG1: April | BK1: May
A2: Task | B2: Status | C2: 2 | D2: 3 | E2: 4 | F2: 5 | G2: 6 | H2: 7 | I2: 8 | J2: 9 | K2: 10 | L2: 11 | M2: 12 | N2: 13 | O2: 14 | P2: 15 | Q2: 16 | R2: 17 | S2: 18 | T2: 19 | U2: 20 | V2: 21 | W2: 22 | X2: 23 | Y2: 24 | Z2: 25 | AA2: 26 | AB2: 27 | AC2: 28 | AD2: 29 | AE2: 30 | AF2: 31 | AG2: 1 | AH2: 2 | AI2: 3 | AJ2: 4 | AK2: 5 | AL2: 6 | AM2: 7 | AN2: 8 | AO2: 9 | AP2: 10 | AQ2: 11 | AR2: 12 | AS2: 13 | AT2: 14 | AU2: 15 | AV2: 16 | AW2: 17 | AX2: 18 | AY2: 19 | AZ2: 20 | BA2: 21 | BB2: 22 | BC2: 23 | BD2: 24 | BE2: 25 | BF2: 26 | BG2: 27 | BH2: 28 | BI2: 29 | BJ2: 30 | BK2: 1 | BL2: 2 | BM2: 3 | BN2: 4 | BO2: 5 | BP2: 6 | BQ2: 7 | BR2: 8 | BS2: 9 | BT2: 10 | BU2: 11 | BV2: 12 | BW2: 13 | BX2: 14 | BY2: 15 | BZ2: 16 | CA2: 17 | CB2: 18 | CC2: 19 | CD2: 20 | CE2: 21 | CF2: 22 | CG2: 23 | CH2: 24 | CI2: 25
A3: DISCOVERY & PLANNING
A4: Discovery & Requirements | B4: Complete
A5: Competitor Analysis | B5: Complete
A6: Sitemap & IA | B6: Complete
A7: Content Audit | B7: Complete
A8: DESIGN & BUILD
A9: Project Setup | B9: Complete
A10: Homepage Build | B10: Complete
A11: Personal/Loan Pages | B11: Complete
A12: Digital Banking Pages | B12: Complete
A13: About/Careers/Tenders | B13: Complete
A14: Navbar, Footer, Components | B14: Complete
A15: Chatbot + GA4 | B15: Complete
A16: CLIENT REVIEW & REVISIONS
A17: First Draft Submitted | B17: Complete
A18: Feedback Round 1 | B18: Complete
A19: Revisions Round 1 | B19: Complete
A20: Business Banking Page | B20: Not Started
A21: Contact Us + FAQs | B21: Not Started
A22: Blog + Privacy/Terms + Cookie | B22: Not Started
A23: Figma Design System | B23: Not Started
A24: AWAITING CLIENT (13 items) | B24: Blocked
A25: Feedback Round 2 | B25: Not Started
A26: Feedback Round 3 (Final) | B26: Not Started
A27: CONTENT & LOCALIZATION
A28: Swahili Translation | B28: Not Started
A29: Branch Directory + Maps | B29: Not Started
A30: API Integrations | B30: Not Started
A31: Final Content & Media | B31: Not Started
A32: TESTING & QA
A33: Cross-Browser Testing | B33: Not Started
A34: SEO & Performance | B34: Not Started
A35: Security & BOT Compliance | B35: Not Started
A36: UAT with CoopBank | B36: Not Started
A37: GO-LIVE & HANDOVER
A38: DNS Migration & Launch | B38: Not Started
A39: Staff Training | B39: Not Started
A40: Post-Launch Monitoring (30d) | B40: Not Started

Sheet Activity Log
A1: Activity Log — Track status changes here
A2: Date | B2: Task ID | C2: Task Name | D2: Field | E2: Old Value | F2: New Value | G2: Changed By
A3: 2026-03-26 | B3: - | C3: Project Tracker Created | D3: Setup | E3: - | F3: All tasks imported from CRM | G3: System

Sheet Stakeholders
A1: Project Stakeholders
A2: Name | B2: Email | C2: Role | D2: Organization | E2: Key Responsibility
A3: Jumbe Seleman | B3: jumbenylon@gmail.com | C3: Lead Developer | D3: Saccura Group | E3: Full-stack dev, architecture, deployment
A4: Mwana Neema Semboja | B4: neema.semboja@sakuragroup.co.tz | C4: Project Manager | D4: Saccura Group | E4: Client liaison, content, PM
A5: Oscar Rubasha | B5: Oscar.Ruhasha@cbtbank.co.tz | C5: Main Feedback Contact | D5: CBT Bank | E5: Primary reviewer — all feedback through Oscar
A6: Moses Mpakasi | B6: Moses.Mpakasi@cbtbank.co.tz | C6: Key Stakeholder | D6: CBT Bank
A7: Yahya Kinabo | B7: Yahya.Kiyabo@cbtbank.co.tz | C7: Key Stakeholder | D7: CBT Bank
A8: Martin Malopa | B8: Martin.Malopa@cbtbank.co.tz | C8: Key Stakeholder | D8: CBT Bank
A9: Geoffrey Nangai | B9: Geoffrey.Nangai@cbtbank.co.tz | C9: Key Stakeholder | D9: CBT Bank
A10: Tecla Muchunguzi | B10: Tecla.Muchunguzi@cbtbank.co.tz | C10: Key Stakeholder | D10: CBT Bank
A11: Samson Msangi | B11: Samson.Msangi@cbtbank.co.tz | C11: Key Stakeholder | D11: CBT Bank
A12: Hemed Nassor | B12: Hemed.Nassor@cbtbank.co.tz | C12: Primary Contact | D12: CBT Bank
A13: Robin Makwabe | B13: Robin.Makwabe@cbtbank.co.tz | C13: Stakeholder (CC) | D13: CBT Bank
